Workbook

Sheet How to use this template
E3: Investment Binder Networth
B6: This template has been made to help you with your investment binder for your banker. There are many formulas in place so that you do not need to do much math and can easily update it. You will only need to enter information once and the formulas will automatically apply that number in other sheets. You will note that some numbers are black and some blue. Blue print is where you can add your own information. Black print is reserved for cells that have formulas (the information is coming from somewhere else in the binder to save you time). So, leave the black ones alone. Note: a lot of the information comes from the appendices, so you may want to start on the last page (furthest right) and work your way to the left). When printing, be sure to select "print black ink only" under page setup so that you don't have a black & blue binder! Have Fun!

Sheet Cashflow
A1: Monthly Cash Flow Summary | B1: (Your Name)
A2: =TODAY() -> 44602 | B2: =TODAY() -> 44602 | C2: =TODAY() -> 44602
A4: INCOME
A5: Monthly Income Sources | B5: Monthly | C5: Totals
A6: Revenue property rental income | B6: ='Real Estate Balance Sheet'!E25 -> 0
A7: Employment or business income | B7: 0
A8: Other Income: | B8: 0
A9: Other Income: | B9: 0
A10: Total Income Per Month | C10: =SUM(B6:B9) -> 0
A12: EXPENSES
A13: Regular Monthly Expenses | B13: Monthly | C13: Totals
A14: Revenue property debt servicing and all other expenses (See Appendix C) | B14: ='Overview Rentals'!F16+'Overview Rentals'!G16 -> 0
A15: Principle residence mortgage (rent or mortgage payments) (See Appendix D) | B15: ='Real Estate Balance Sheet'!G8 -> 0
A16: Utilities: heat, light, telephone, internet,alarm, cable, city tax | B16: 0
A17: Automobile transportation: gasoline, maintenance, parking | B17: 0
A18: Groceries and other household supplies | B18: 0
A19: Clothing: including work clothes, sportswear, repairs, accessories | B19: 0
A20: Life Insurance premiums | B20: 0
A21: Medical & Dental Care: including prescription drugs and deductible expenses | B21: 0
A22: Consumer Credit Payments: department store accounts, credit cards etc. | B22: 0
A23: Other Personal Spending: grooming aids, haircuts, dry-cleaning, etc. | B23: 0 | C23: =SUM(B14:B23) -> 0
A24: Discretionary Spending | B24: Monthly | C24: Totals
A25: Savings: retirement fund, vacation fund | B25: 0
A26: Educational Expenses: tuitions, books, materials | B26: 0
A27: Entertainment: dining, theatre tickets, printed materials, etc. | B27: 0
A28: Gifts: special occasions, charitable donations, etc. | B28: 0
A29: Miscellaneous: long-distance phone/fax calls, lunches & snacks, indulgences.... | B29: 0 | C29: =SUM(B25:B29) -> 0
A30: Occasional Expenses (including regular non-monthly payments) | B30: Annually | C30: Monthly
A31: Home Insurance: paid annually | B31: 0 | C31: =B31/12 -> 0
A32: Auto Insurance: paid annually | B32: 0 | C32: =B32/12 -> 0
A33: Recreational and/or club memberships: paid quarterly | B33: 0 | C33: =(B33*4)/12 -> 0
A34: Furniture & Appliance Purchases & Repairs: occasional expenses | B34: 0 | C34: =B34/12 -> 0
A35: Other | B35: 0 | C35: =B35/12 -> 0
A36: Other | B36: 0 | C36: =B36/12 -> 0
A37: Other | B37: 0 | C37: =B37/12 -> 0
A38: Total Expenses Per Month | C38: =SUM(C29,C23,C31:C37) -> 0
A40: MONTHLY RESIDUAL INCOME: | B40: =C10-C38 -> 0

Sheet Balance Statement
A1: Balance Statement | E1: (Your Name)
A2: =TODAY() -> 44602
A4: ASSETS | D4: LIABILITIES | G4: INSURANCE
A6: Deposit Accounts (banks,trust co.'s, etc.) | D6: Mortgages | H6: Policy Number | I6: Sum Insured | J6: Total Less Loans
A7: Chequing/Savings Accounts (Appendix B) | B7: ='RRSP & Credit'!C61 -> 0 | D7: Rental Properties (See Appendix C) | E7: ='Real Estate Balance Sheet'!F25 -> 0 | G7: Name Insured | H7: #############
A8: Joint Accounts (Appendix B) | B8: ='RRSP & Credit'!C70 -> 0 | D8: Principle Residence (See Appendix D) | E8: ='Real Estate Balance Sheet'!F13 -> 25000 | G8: Name Insured | H8: #############
A9: TOTAL Deposit Accounts | B9: =SUM(B7:B8) -> 0 | D9: TOTAL Mortgages | E9: =SUM(E7:E8) -> 25000 | G9: Name Insured | H9: #############
G10: Name Insured | H10: #############
A11: Investments (registered & unregistered funds) | G11: Name Insured | H11: #############
A12: RRSP/Investment Portfolio (Appendix A) | B12: ='RRSP & Credit'!D23 -> 0 | D12: Consumer Loans (Appendix B) | G12: Name Insured | H12: #############
A13: Life Insurance | B13: =J14 -> 0 | D13: TOTAL Loans, Lines of Credit | E13: ='RRSP & Credit'!C40 -> 0 | G13: Name Insured | H13: #############
A14: TOTAL Investments | B14: =SUM(B12:B13) -> 0 | J14: =SUM(J7:J13) -> 0
A16: Real Estate Portfolio | D16: Accounts Payable (See Appendix B)
A17: Rental Property Portfolio (Appendix C) | B17: ='Overview Rentals'!D16 -> 0 | D17: TOTAL Accounts Payable | E17: ='RRSP & Credit'!C48 -> 0
A18: Principal Residence and other property (Appendix D) | B18: ='Real Estate Balance Sheet'!D13 -> 750000
A19: TOTAL Real Estate Portfolio | B19: =(B17+B18) -> 750000
A21: Goods and Chattels
A22: Gold, Silver, Diamonds, Jewelry | B22: 0
A23: Antiques | B23: 0
A24: Vehicle 1 | B24: 0
A25: Vehicle 2 | B25: 0
A26: Furniture & Appliances | B26: 0
A27: Business Equipment | B27: 0
A28: Electronics | B28: 0
A29: Other | B29: 0
A30: Other | B30: 0
A31: Other | B31: 0
A32: TOTAL Goods and Chattels | B32: =SUM(B22:B31) -> 0
A34: TOTAL ASSETS | B34: =B9+B14+B32+B19 -> 750000 | D34: TOTAL LIABILITIES | E34: =E17+E13+E9 -> 25000
A36: Net Worth | B36: =B34-E34 -> 725000

Sheet RRSP & Credit
A1: Appendix A
A2: RRSP / RRIF / Investment Portfolio of | E2: (Your Name)
A3: =TODAY() -> 44602
A6: Mutual Funds, RRSP’s / RRIF’s, Stocks, Bonds, GIC's | B6: Account No. | C6: Date of Last Statement | F6: Share Price | G6: No. of Shares
D7: =F7*G7 -> 0
D8: =F8*G8 -> 0
D9: =F9*G9 -> 0
D10: =F10*G10 -> 0
D11: =F11*G11 -> 0
D12: =F12*G12 -> 0
D13: =F13*G13 -> 0
D14: =F14*G14 -> 0
D15: =F15*G15 -> 0
D16: =F16*G16 -> 0
D17: =F17*G17 -> 0
D18: =F18*G18 -> 0
... D22: =F22*G22 -> 0
A23: TOTAL Mutual Fund RRSP’s / RRIF’s | D23: =SUM(D7:D22) -> 0
A26: Appendix B
A27: Credit Status
A28: =TODAY() -> 44602
B30: Monthly | C30: Current | D30: Funds | F30: Credit Limit | G30: Min Pymt
A31: Lines of Credit, Personal Loans: | B31: Payments | C31: Balance | D31: Available
B32: =(C32*G32)/12 -> 0 | D32: =F32-C32 -> 0 | G32: 0.04
B33: =(C33*G33)/12 -> 0 | D33: =F33-C33 -> 0 | G33: 0.08
B34: =(C34*G34)/12 -> 0 | D34: =F34-C34 -> 0
B35: =(C35*G35)/12 -> 0 | D35: =F35-C35 -> 0
B36: =(C36*G36)/12 -> 0 | D36: =F36-C36 -> 0
B37: =(C37*G37)/12 -> 0 | D37: =F37-C37 -> 0
B38: =(C38*G38)/12 -> 0 | D38: =F38-C38 -> 0
B39: =(C39*G39)/12 -> 0 | D39: =F39-C39 -> 0
A40: TOTAL for Lines of Credit | B40: =SUM(B32:B39) -> 0 | C40: =SUM(C32:C39) -> 0 | D40: =SUM(D32:D39) -> 0
A42: Credit Cards | F42: Credit Limit
B43: =(C43*G43)/12 -> 0 | D43: =F43-C43 -> 0 | F43: 0
B44: =(C44*G44)/12 -> 0 | D44: =F44-C44 -> 0 | F44: 0
B45: =(C45*G45)/12 -> 0 | D45: =F45-C45 -> 0 | F45: 0
B46: =(C46*G46)/12 -> 0 | F46: 0
B47: =(C47*G47)/12 -> 0 | D47: 0
A48: TOTALS for Credit Cards | B48: =SUM(B43:B47) -> 0 | C48: =SUM(C43:C47) -> 0 | D48: =SUM(D43:D47) -> 0
A50: Chequing/Savings Accounts
...

Sheet Overview Rentals
A1: Appendix C
A2: Overview of Rental Properties | E2: (Your Name)
A3: =TODAY() -> 44602
A5: # | B5: Property Address & Mortgage Information: | C5: Year Purch | D5: Current Value | E5: Mortgage Balance | F5: Mortgage Payment | G5: Taxes (Monthly) | H5: Rental Income
A6: 1 | B6: ='Real Estate Balance Sheet'!B16 -> Rental Property Address 1 | D6: ='Real Estate Balance Sheet'!D16 -> 0 | E6: ='Real Estate Balance Sheet'!F16 -> 0 | F6: ='Real Estate Balance Sheet'!G16 -> 0 | H6: ='Real Estate Balance Sheet'!E16 -> 0
A7: 2 | B7: ='Real Estate Balance Sheet'!B17 -> 0 | D7: ='Real Estate Balance Sheet'!D17 -> 0 | E7: ='Real Estate Balance Sheet'!F17 -> 0 | F7: ='Real Estate Balance Sheet'!G17 -> 0 | H7: ='Real Estate Balance Sheet'!E17 -> 0 | J7: (divide total tax by 12)
A8: 3 | B8: ='Real Estate Balance Sheet'!B18 -> 0 | E8: ='Real Estate Balance Sheet'!F18 -> 0 | F8: ='Real Estate Balance Sheet'!G18 -> 0 | H8: ='Real Estate Balance Sheet'!E18 -> 0
A9: 4 | B9: ='Real Estate Balance Sheet'!B19 -> 0 | D9: ='Real Estate Balance Sheet'!D19 -> 0 | E9: ='Real Estate Balance Sheet'!F19 -> 0 | F9: ='Real Estate Balance Sheet'!G19 -> 0 | H9: ='Real Estate Balance Sheet'!E19 -> 0
A10: 5 | B10: ='Real Estate Balance Sheet'!B20 -> 0 | D10: ='Real Estate Balance Sheet'!D20 -> 0 | E10: ='Real Estate Balance Sheet'!F20 -> 0 | F10: ='Real Estate Balance Sheet'!G20 -> 0 | H10: ='Real Estate Balance Sheet'!E20 -> 0
A11: 6 | B11: ='Real Estate Balance Sheet'!B21 -> 0 | D11: ='Real Estate Balance Sheet'!D21 -> 0 | E11: ='Real Estate Balance Sheet'!F21 -> 0 | F11: ='Real Estate Balance Sheet'!G21 -> 0 | H11: ='Real Estate Balance Sheet'!E21 -> 0
A12: 7 | B12: ='Real Estate Balance Sheet'!B22 -> 0 | D12: ='Real Estate Balance Sheet'!D22 -> 0 | E12: ='Real Estate Balance Sheet'!F22 -> 0 | F12: ='Real Estate Balance Sheet'!G22 -> 0 | H12: ='Real Estate Balance Sheet'!E22 -> 0
A13: 8 | B13: ='Real Estate Balance Sheet'!B23 -> 0 | D13: ='Real Estate Balance Sheet'!D23 -> 0 | E13: ='Real Estate Balance Sheet'!F23 -> 0 | F13: ='Real Estate Balance Sheet'!G23 -> 0 | H13: ='Real Estate Balance Sheet'!E23 -> 0
A14: 9 | B14: ='Real Estate Balance Sheet'!B24 -> 0 | D14: ='Real Estate Balance Sheet'!D24 -> 0 | E14: ='Real Estate Balance Sheet'!F24 -> 0 | F14: ='Real Estate Balance Sheet'!G24 -> 0 | H14: ='Real Estate Balance Sheet'!E24 -> 0
B16: TOTALS FOR ALL REVENUE PROPERTIES | D16: =SUM(D6:D15) -> 0 | E16: =SUM(E6:E15) -> 0 | F16: =SUM(F6:F15) -> 0 | G16: =SUM(G6:G15) -> 0 | H16: =SUM(H6:H15) -> 0

Sheet Real Estate Balance Sheet
A1: Appendix D
A2: Real Estate Assets and Liabilities | F2: (Your Name)
A3: =TODAY() -> 44602
B5: Real Estate Assets | F5: Real Estate Liabilities
A7: # | B7: Personal Properties: | C7: Equity | D7: Current Value | E7: Rent | F7: Mortgage Balance | G7: Monthly Pmt. | H7: Loan to Value
A8: 1 | B8: Principle Residence: your address | C8: =D8-F8 -> 500000 | D8: 500000 | E8: 0 | F8: 0 | G8: 0 | H8: =F8/D8 -> 0
A9: 2 | B9: Address 2 | C9: =D9-F9 -> 225000 | D9: 250000 | E9: 0 | F9: 25000 | G9: 0 | H9: =F9/D9 -> 0.1
A10: 3 | C10: =D10-F10 -> 0 | H10: =F10/D10 -> #DIV/0!
A11: 4 | C11: =D11-F11 -> 0 | H11: =F11/D11 -> #DIV/0!
A12: 5 | C12: =D12-F12 -> 0 | H12: =F12/D12 -> #DIV/0!
B13: Total Personal Real Estate Owned | C13: =SUM(C8:C12) -> 725000 | D13: =SUM(D8:D12) -> 750000 | E13: =SUM(E8:E12) -> 0 | F13: =SUM(F8:F12) -> 25000 | G13: =SUM(G8:G12) -> 0 | H13: =F13/D13 -> 0.033333333
B15: Rental Properties:
A16: 1 | B16: Rental Property Address 1 | C16: =D16-F16 -> 0 | H16: =F16/D16 -> #DIV/0!
A17: 2 | C17: =D17-F17 -> 0 | H17: =F17/D17 -> #DIV/0!
A18: 3 | C18: =D18-F18 -> 0 | H18: =F18/D18 -> #DIV/0!
A19: 4 | C19: =D19-F19 -> 0 | H19: =F19/D19 -> #DIV/0!
A20: 5 | C20: =D20-F20 -> 0 | H20: =F20/D20 -> #DIV/0!
A21: 6 | C21: =D21-F21 -> 0 | H21: =F21/D21 -> #DIV/0!
A22: 7 | C22: =D22-F22 -> 0 | H22: =F22/D22 -> #DIV/0!
A23: 8 | C23: =D23-F23 -> 0 | H23: =F23/D23 -> #DIV/0!
A24: 9 | C24: =D24-F24 -> 0 | H24: =F24/D24 -> #DIV/0!
B25: Total Rental Property | C25: =SUM(C16:C24) -> 0 | D25: =SUM(D16:D24) -> 0 | E25: =SUM(E16:E24) -> 0 | F25: =SUM(F16:F24) -> 0 | G25: =SUM(G16:G24) -> 0 | H25: =F25/D25 -> #DIV/0!
B27: Totals for all Real Estate | C27: =C25+C13 -> 725000 | D27: =D25+D13 -> 750000 | E27: =E25+E13 -> 0 | F27: =F25+F13 -> 25000 | G27: =G25+G13 -> 0 | H27: =F27/D27 -> 0.033333333
